Workbook

Sheet Assumptions
A1: Meridian Solar IPP — 50 MW
A2: Assumptions Tab — all model inputs live here
A3: Colour key: BLUE = hardcoded input | BLACK = formula / calculation | GREEN = link from another tab
A4: All currency in USD millions unless stated otherwise.
A6: 1. PROJECT & TECHNICAL | B6: Value | C6: Unit | D6: Note / source
A7: Installed capacity | B7: 50 | C7: MW | D7: Case assumption
A8: Hours per year | B8: 8760 | C8: hours | D8: Case assumption (365 x 24)
A9: Net capacity factor | B9: 0.21 | C9: % | D9: Applied to gross generation — key sensitivity driver
A10: Gross generation at 100% capacity factor | B10: =B7*1000*B8/1000000 -> 438 | C10: GWh | D10: = Capacity (MW) x 1,000 x hours
A11: Net annual generation | B11: =B10*B9 -> 91.98 | C11: GWh | D11: = Gross generation x net capacity factor
A12: Net annual generation | B12: =B11*1000000 -> 91980000 | C12: kWh | D12: Flat across all 20 years — no panel degradation assumed (see note below)
A14: 2. CONSTRUCTION & CAPEX | B14: Value | C14: Unit | D14: Note / source
A15: Total construction cost (capex) | B15: 60 | C15: USD m | D15: Incurred evenly over a 12-month build
A16: Implied capex per MW | B16: =B15/B7 -> 1.2 | C16: USD m / MW | D16: Sanity check — in line with utility-scale solar benchmarks
A17: Construction period | B17: 12 | C17: months | D17: Single construction year (Year 0 = calendar 2026)
A18: Construction start | B18: 46023 | C18: date | D18: Assumption — 12 months before COD
A19: Commercial operation date (COD) | B19: 46388 | C19: date | D19: Year 1 of operations
A20: Operating life / PPA term | B20: 20 | C20: years | D20: 20-year take-or-pay PPA
A22: 3. REVENUE & OPERATING COSTS | B22: Value | C22: Unit | D22: Note / source
A23: PPA tariff — Year 1 | B23: 0.075 | C23: USD / kWh | D23: 20-year take-or-pay PPA — key sensitivity driver
A24: Tariff escalation (from Year 2) | B24: 0.015 | C24: % p.a. | D24: Contractual indexation
A25: Implied Year 1 revenue | B25: =B12*B23/1000000 -> 6.8985 | C25: USD m | D25: Cross-check against Model tab
A26: Operating cost — Year 1 | B26: 1.2 | C26: USD m | D26: O&M, insurance, land, admin
A27: Operating cost escalation (from Year 2) | B27: 0.03 | C27: % p.a. | D27: Assumed local inflation proxy
A28: Implied Year 1 EBITDA margin | B28: =(B25-B26)/B25 -> 0.82604914 | C28: % | D28: Sanity check — typical for solar IPP with low variable cost
A30: 4. DEPRECIATION, TAX & DISCOUNTING | B30: Value | C30: Unit | D30: Note / source
A31: Depreciation life (straight-line) | B31: 20 | C31: years | D31: Asset fully depreciated over the PPA term
A32: Annual depreciation charge | B32: =B15/B31 -> 3 | C32: USD m | D32: = Capex / depreciation life
A33: Corporate tax rate | B33: 0.3 | C33: % | D33: Tax paid in the year incurred; no loss carry-forward modelled
A34: Project discount rate (unlevered WACC) | B34: 0.1 | C34: % | D34: Prescribed by the case for project NPV
A36: 5. SECTION C — Domestic Infrastructure Fund SENIOR DEBT TERMS | B36: Value | C36: Unit | D36: Note / source
A37: Maximum gearing (debt as % of project cost) | B37: 0.7 | C37: % | D37: DIF cap — 70:30 debt:equity
A38: Debt tenor from COD | B38: 15 | C38: years | D38: DIF maximum tenor
A39: Interest rate on drawn senior debt | B39: 0.08 | C39: % p.a. | D39: DIF term sheet
A40: Minimum DSCR covenant | B40: 1.3 | C40: x | D40: Hard covenant — must be met in every period
A41: Target sculpting DSCR | B41: 1.3 | C41: x | D41: Debt service sculpted to this DSCR; set = covenant to maximise capacity
A42: DSRA — months of forward debt service | B42: 6 | C42: months | D42: Funded at COD from equity; released on final repayment
A43: Cash sweep — % of surplus cash | B43: 0.5 | C43: % | D43: Applied after scheduled debt service, until debt repaid
A44: Cash sweep switch (1 = on, 0 = off) | B44: 1 | C44: flag | D44: Toggle to show the schedule with and without the sweep
A45: Maximum debt by gearing cap | B45: =B37*B15 -> 42 | C45: USD m | D45: = 70% x total project cost
...

Sheet Model
A1: Meridian Solar IPP — PROJECT FINANCE MODEL (SECTION A)
A2: Unlevered project cash flows. All figures USD m unless stated. Green = link to Assumptions tab.
A4: Period (year from COD) | B4: Unit | C4: 0 | D4: =C4+1 -> 1 | E4: =D4+1 -> 2 | F4: =E4+1 -> 3 | G4: =F4+1 -> 4 | H4: =G4+1 -> 5 | I4: =H4+1 -> 6 | J4: =I4+1 -> 7 | K4: =J4+1 -> 8 | ... W4: =V4+1 -> 20
A5: Calendar year | C5: =YEAR(Assumptions!$B$18) -> 2026 | D5: =C5+1 -> 2027 | E5: =D5+1 -> 2028 | F5: =E5+1 -> 2029 | G5: =F5+1 -> 2030 | H5: =G5+1 -> 2031 | I5: =H5+1 -> 2032 | J5: =I5+1 -> 2033 | K5: =J5+1 -> 2034 | ... W5: =V5+1 -> 2046
A6: Phase | C6: =IF(C4=0,"Construction","Operations") -> Construction | D6: =IF(D4=0,"Construction","Operations") -> Operations | E6: =IF(E4=0,"Construction","Operations") -> Operations | F6: =IF(F4=0,"Construction","Operations") -> Operations | G6: =IF(G4=0,"Construction","Operations") -> Operations | H6: =IF(H4=0,"Construction","Operations") -> Operations | I6: =IF(I4=0,"Construction","Operations") -> Operations | J6: =IF(J4=0,"Construction","Operations") -> Operations | ... W6: =IF(W4=0,"Construction","Operations") -> Operations
A7: Operating period flag | C7: =IF(AND(C4>=1,C4<=Assumptions!$B$20),1,0) -> 0 | D7: =IF(AND(D4>=1,D4<=Assumptions!$B$20),1,0) -> 1 | E7: =IF(AND(E4>=1,E4<=Assumptions!$B$20),1,0) -> 1 | F7: =IF(AND(F4>=1,F4<=Assumptions!$B$20),1,0) -> 1 | G7: =IF(AND(G4>=1,G4<=Assumptions!$B$20),1,0) -> 1 | H7: =IF(AND(H4>=1,H4<=Assumptions!$B$20),1,0) -> 1 | I7: =IF(AND(I4>=1,I4<=Assumptions!$B$20),1,0) -> 1 | J7: =IF(AND(J4>=1,J4<=Assumptions!$B$20),1,0) -> 1 | ... W7: =IF(AND(W4>=1,W4<=Assumptions!$B$20),1,0) -> 1
A9: REVENUE BUILD
A10: Net generation | B10: GWh | C10: =C7*Assumptions!$B$11 -> 0 | D10: =D7*Assumptions!$B$11 -> 91.98 | E10: =E7*Assumptions!$B$11 -> 91.98 | F10: =F7*Assumptions!$B$11 -> 91.98 | G10: =G7*Assumptions!$B$11 -> 91.98 | H10: =H7*Assumptions!$B$11 -> 91.98 | I10: =I7*Assumptions!$B$11 -> 91.98 | J10: =J7*Assumptions!$B$11 -> 91.98 | ... W10: =W7*Assumptions!$B$11 -> 91.98
A11: PPA tariff | B11: USD/kWh | C11: =IF(C7=0,0,Assumptions!$B$23*(1+Assumptions!$B$24)^(C4-1)) -> 0 | D11: =IF(D7=0,0,Assumptions!$B$23*(1+Assumptions!$B$24)^(D4-1)) -> 0.075 | E11: =IF(E7=0,0,Assumptions!$B$23*(1+Assumptions!$B$24)^(E4-1)) -> 0.076125 | F11: =IF(F7=0,0,Assumptions!$B$23*(1+Assumptions!$B$24)^(F4-1)) -> 0.077266875 | G11: =IF(G7=0,0,Assumptions!$B$23*(1+Assumptions!$B$24)^(G4-1)) -> 0.078425878 | H11: =IF(H7=0,0,Assumptions!$B$23*(1+Assumptions!$B$24)^(H4-1)) -> 0.079602266 | I11: =IF(I7=0,0,Assumptions!$B$23*(1+Assumptions!$B$24)^(I4-1)) -> 0.0807963 | J11: =IF(J7=0,0,Assumptions!$B$23*(1+Assumptions!$B$24)^(J4-1)) -> 0.082008245 | ... W11: =IF(W7=0,0,Assumptions!$B$23*(1+Assumptions!$B$24)^(W4-1)) -> 0.099521306
A12: Revenue | B12: USD m | C12: =C10*C11 -> 0 | D12: =D10*D11 -> 6.8985 | E12: =E10*E11 -> 7.0019775 | F12: =F10*F11 -> 7.1070072 | G12: =G10*G11 -> 7.2136123 | H12: =H10*H11 -> 7.3218165 | I12: =I10*I11 -> 7.4316437 | J12: =J10*J11 -> 7.5431184 | ... W12: =W10*W11 -> 9.1539697
A14: OPERATING COSTS
A15: Operating cost (O&M, insurance, admin) | B15: USD m | C15: =-IF(C7=0,0,Assumptions!$B$26*(1+Assumptions!$B$27)^(C4-1)) -> 0 | D15: =-IF(D7=0,0,Assumptions!$B$26*(1+Assumptions!$B$27)^(D4-1)) -> -1.2 | E15: =-IF(E7=0,0,Assumptions!$B$26*(1+Assumptions!$B$27)^(E4-1)) -> -1.236 | F15: =-IF(F7=0,0,Assumptions!$B$26*(1+Assumptions!$B$27)^(F4-1)) -> -1.27308 | G15: =-IF(G7=0,0,Assumptions!$B$26*(1+Assumptions!$B$27)^(G4-1)) -> -1.3112724 | H15: =-IF(H7=0,0,Assumptions!$B$26*(1+Assumptions!$B$27)^(H4-1)) -> -1.3506106 | I15: =-IF(I7=0,0,Assumptions!$B$26*(1+Assumptions!$B$27)^(I4-1)) -> -1.3911289 | J15: =-IF(J7=0,0,Assumptions!$B$26*(1+Assumptions!$B$27)^(J4-1)) -> -1.4328628 | ... W15: =-IF(W7=0,0,Assumptions!$B$26*(1+Assumptions!$B$27)^(W4-1)) -> -2.1042073
A17: EBITDA | B17: USD m | C17: =C12+C15 -> 0 | D17: =D12+D15 -> 5.6985 | E17: =E12+E15 -> 5.7659775 | F17: =F12+F15 -> 5.8339272 | G17: =G12+G15 -> 5.9023399 | H17: =H12+H15 -> 5.9712059 | I17: =I12+I15 -> 6.0405148 | J17: =J12+J15 -> 6.1102556 | ... W17: =W12+W15 -> 7.0497625
A18: EBITDA margin | B18: % | C18: =IF(C12=0,0,C17/C12) -> 0 | D18: =IF(D12=0,0,D17/D12) -> 0.82604914 | E18: =IF(E12=0,0,E17/E12) -> 0.82347844 | F18: =IF(F12=0,0,F17/F12) -> 0.82086975 | G18: =IF(G12=0,0,G17/G12) -> 0.8182225 | H18: =IF(H12=0,0,H17/H12) -> 0.81553613 | I18: =IF(I12=0,0,I17/I12) -> 0.81281007 | J18: =IF(J12=0,0,J17/J12) -> 0.81004371 | ... W18: =IF(W12=0,0,W17/W12) -> 0.77013172
A20: DEPRECIATION, TAX & ASSET BASE
A21: Opening net book value | B21: USD m | C21: 0 | D21: =C24 -> 60 | E21: =D24 -> 57 | F21: =E24 -> 54 | G21: =F24 -> 51 | H21: =G24 -> 48 | I21: =H24 -> 45 | J21: =I24 -> 42 | K21: =J24 -> 39 | ... W21: =V24 -> 3
A22: Add: capex additions | B22: USD m | C22: =IF(C4=0,Assumptions!$B$15,0) -> 60 | D22: =IF(D4=0,Assumptions!$B$15,0) -> 0 | E22: =IF(E4=0,Assumptions!$B$15,0) -> 0 | F22: =IF(F4=0,Assumptions!$B$15,0) -> 0 | G22: =IF(G4=0,Assumptions!$B$15,0) -> 0 | H22: =IF(H4=0,Assumptions!$B$15,0) -> 0 | I22: =IF(I4=0,Assumptions!$B$15,0) -> 0 | J22: =IF(J4=0,Assumptions!$B$15,0) -> 0 | ... W22: =IF(W4=0,Assumptions!$B$15,0) -> 0
A23: Less: depreciation charge | B23: USD m | C23: =-IF(AND(C4>=1,C4<=Assumptions!$B$31),Assumptions!$B$32,0) -> 0 | D23: =-IF(AND(D4>=1,D4<=Assumptions!$B$31),Assumptions!$B$32,0) -> -3 | E23: =-IF(AND(E4>=1,E4<=Assumptions!$B$31),Assumptions!$B$32,0) -> -3 | F23: =-IF(AND(F4>=1,F4<=Assumptions!$B$31),Assumptions!$B$32,0) -> -3 | G23: =-IF(AND(G4>=1,G4<=Assumptions!$B$31),Assumptions!$B$32,0) -> -3 | H23: =-IF(AND(H4>=1,H4<=Assumptions!$B$31),Assumptions!$B$32,0) -> -3 | I23: =-IF(AND(I4>=1,I4<=Assumptions!$B$31),Assumptions!$B$32,0) -> -3 | J23: =-IF(AND(J4>=1,J4<=Assumptions!$B$31),Assumptions!$B$32,0) -> -3 | ... W23: =-IF(AND(W4>=1,W4<=Assumptions!$B$31),Assumptions!$B$32,0) -> -3
A24: Closing net book value | B24: USD m | C24: =C21+C22+C23 -> 60 | D24: =D21+D22+D23 -> 57 | E24: =E21+E22+E23 -> 54 | F24: =F21+F22+F23 -> 51 | G24: =G21+G22+G23 -> 48 | H24: =H21+H22+H23 -> 45 | I24: =I21+I22+I23 -> 42 | J24: =J21+J22+J23 -> 39 | ... W24: =W21+W22+W23 -> 0
A26: EBIT (EBITDA less depreciation) | B26: USD m | C26: =C17+C23 -> 0 | D26: =D17+D23 -> 2.6985 | E26: =E17+E23 -> 2.7659775 | F26: =F17+F23 -> 2.8339272 | G26: =G17+G23 -> 2.9023399 | H26: =H17+H23 -> 2.9712059 | I26: =I17+I23 -> 3.0405148 | J26: =J17+J23 -> 3.1102556 | ... W26: =W17+W23 -> 4.0497625
A27: Tax at corporate rate (unlevered basis) | B27: USD m | C27: =-MAX(0,C26)*Assumptions!$B$33 -> 0 | D27: =-MAX(0,D26)*Assumptions!$B$33 -> -0.80955 | E27: =-MAX(0,E26)*Assumptions!$B$33 -> -0.82979325 | F27: =-MAX(0,F26)*Assumptions!$B$33 -> -0.85017815 | G27: =-MAX(0,G26)*Assumptions!$B$33 -> -0.87070196 | H27: =-MAX(0,H26)*Assumptions!$B$33 -> -0.89136176 | I27: =-MAX(0,I26)*Assumptions!$B$33 -> -0.91215444 | J27: =-MAX(0,J26)*Assumptions!$B$33 -> -0.93307668 | ... W27: =-MAX(0,W26)*Assumptions!$B$33 -> -1.2149287
A28: Check: taxable profit not negative | B28: flag | C28: =IF(C26<0,"LOSS","ok") -> ok | D28: =IF(D26<0,"LOSS","ok") -> ok | E28: =IF(E26<0,"LOSS","ok") -> ok | F28: =IF(F26<0,"LOSS","ok") -> ok | G28: =IF(G26<0,"LOSS","ok") -> ok | H28: =IF(H26<0,"LOSS","ok") -> ok | I28: =IF(I26<0,"LOSS","ok") -> ok | J28: =IF(J26<0,"LOSS","ok") -> ok | ... W28: =IF(W26<0,"LOSS","ok") -> ok
A30: CASH FLOW
A31: EBITDA | B31: USD m | C31: =C17 -> 0 | D31: =D17 -> 5.6985 | E31: =E17 -> 5.7659775 | F31: =F17 -> 5.8339272 | G31: =G17 -> 5.9023399 | H31: =H17 -> 5.9712059 | I31: =I17 -> 6.0405148 | J31: =J17 -> 6.1102556 | ... W31: =W17 -> 7.0497625
A32: Less: cash tax (unlevered) | B32: USD m | C32: =C27 -> 0 | D32: =D27 -> -0.80955 | E32: =E27 -> -0.82979325 | F32: =F27 -> -0.85017815 | G32: =G27 -> -0.87070196 | H32: =H27 -> -0.89136176 | I32: =I27 -> -0.91215444 | J32: =J27 -> -0.93307668 | ... W32: =W27 -> -1.2149287
A33: Less: change in net working capital | B33: USD m | C33: 0 | D33: 0 | E33: 0 | F33: 0 | G33: 0 | H33: 0 | I33: 0 | J33: 0 | K33: 0 | L33: 0 | M33: 0 | N33: 0 | O33: 0 | P33: 0 | Q33: 0 | R33: 0 | S33: 0 | T33: 0 | U33: 0 | V33: 0 | W33: 0
A34: CFADS — CASH FLOW AVAILABLE FOR DEBT SERVICE | B34: USD m | C34: =C31+C32+C33 -> 0 | D34: =D31+D32+D33 -> 4.88895 | E34: =E31+E32+E33 -> 4.9361842 | F34: =F31+F32+F33 -> 4.983749 | G34: =G31+G32+G33 -> 5.0316379 | H34: =H31+H32+H33 -> 5.0798441 | I34: =I31+I32+I33 -> 5.1283604 | J34: =J31+J32+J33 -> 5.1771789 | ... W34: =W31+W32+W33 -> 5.8348337
A36: Less: capex | B36: USD m | C36: =-C22 -> -60 | D36: =-D22 -> 0 | E36: =-E22 -> 0 | F36: =-F22 -> 0 | G36: =-G22 -> 0 | H36: =-H22 -> 0 | I36: =-I22 -> 0 | J36: =-J22 -> 0 | ... W36: =-W22 -> 0
A37: UNLEVERED FREE CASH FLOW (PROJECT FCF) | B37: USD m | C37: =C34+C36 -> -60 | D37: =D34+D36 -> 4.88895 | E37: =E34+E36 -> 4.9361842 | F37: =F34+F36 -> 4.983749 | G37: =G34+G36 -> 5.0316379 | H37: =H34+H36 -> 5.0798441 | I37: =I34+I36 -> 5.1283604 | J37: =J34+J36 -> 5.1771789 | ... W37: =W34+W36 -> 5.8348337
A38: Cumulative unlevered free cash flow | B38: USD m | C38: =C37 -> -60 | D38: =C38+D37 -> -55.11105 | E38: =D38+E37 -> -50.174866 | F38: =E38+F37 -> -45.191117 | G38: =F38+G37 -> -40.159479 | H38: =G38+H37 -> -35.079635 | I38: =H38+I37 -> -29.951274 | J38: =I38+J37 -> -24.774095 | K38: =J38+K37 -> -19.547804 | ... W38: =V38+W37 -> 47.091918
A39: Discount factor at project discount rate | B39: x | C39: =1/(1+Assumptions!$B$34)^C4 -> 1 | D39: =1/(1+Assumptions!$B$34)^D4 -> 0.90909091 | E39: =1/(1+Assumptions!$B$34)^E4 -> 0.82644628 | F39: =1/(1+Assumptions!$B$34)^F4 -> 0.7513148 | G39: =1/(1+Assumptions!$B$34)^G4 -> 0.68301346 | H39: =1/(1+Assumptions!$B$34)^H4 -> 0.62092132 | I39: =1/(1+Assumptions!$B$34)^I4 -> 0.56447393 | J39: =1/(1+Assumptions!$B$34)^J4 -> 0.51315812 | ... W39: =1/(1+Assumptions!$B$34)^W4 -> 0.14864363
A40: PV of unlevered free cash flow | B40: USD m | C40: =C37*C39 -> -60 | D40: =D37*D39 -> 4.4445 | E40: =E37*E39 -> 4.0794911 | F40: =F37*F39 -> 3.7443644 | G40: =G37*G39 -> 3.4366764 | H40: =H37*H39 -> 3.1541835 | I40: =I37*I39 -> 2.8948257 | J40: =J37*J39 -> 2.6567114 | ... W40: =W37*W39 -> 0.86731085
A42: PROJECT RETURNS — UNLEVERED | C42: Value
A43: Project IRR (unlevered) | B43: % | C43: =IRR(C37:W37) -> 0.060665745
A44: Project NPV at discount rate (sum of PV row) | B44: USD m | C44: =SUM(C40:W40) -> -15.678691
A45: Cross-check: NPV via NPV() function | B45: USD m | C45: =C37+NPV(Assumptions!$B$34,D37:W37) -> -15.678691
A46: Check: two NPV methods agree | B46: flag | C46: =IF(ABS(C44-C45)<0.001,"ok","CHECK") -> ok
A47: Simple payback (years from COD, undiscounted) | B47: years | C47: =IF(W38<0,"Not repaid",COUNTIF(D38:W38,"<0")+1) -> 12
A48: Undiscounted cash-on-cash multiple | B48: x | C48: =SUM(D37:W37)/-C37 -> 1.7848653
A49: Total lifetime generation | B49: GWh | C49: =SUM(C10:W10) -> 1839.6
...

Sheet Debt
A1: DIF SENIOR DEBT PACKAGE — Meridian Solar IPP (SECTION C)
A2: Debt sized off the Model tab CFADS line. Repayment sculpted to the target DSCR. All figures USD m.
A4: Period (year from COD) | B4: Unit | C4: =Model!C4 -> 0 | D4: =Model!D4 -> 1 | E4: =Model!E4 -> 2 | F4: =Model!F4 -> 3 | G4: =Model!G4 -> 4 | H4: =Model!H4 -> 5 | I4: =Model!I4 -> 6 | J4: =Model!J4 -> 7 | ... W4: =Model!W4 -> 20
A5: Calendar year | C5: =Model!C5 -> 2026 | D5: =Model!D5 -> 2027 | E5: =Model!E5 -> 2028 | F5: =Model!F5 -> 2029 | G5: =Model!G5 -> 2030 | H5: =Model!H5 -> 2031 | I5: =Model!I5 -> 2032 | J5: =Model!J5 -> 2033 | ... W5: =Model!W5 -> 2046
A7: 1. DEBT SIZING — WHICH CONSTRAINT BINDS?
A8: CFADS (link from Model tab) | B8: USD m | C8: =Model!C34 -> 0 | D8: =Model!D34 -> 4.88895 | E8: =Model!E34 -> 4.9361842 | F8: =Model!F34 -> 4.983749 | G8: =Model!G34 -> 5.0316379 | H8: =Model!H34 -> 5.0798441 | I8: =Model!I34 -> 5.1283604 | J8: =Model!J34 -> 5.1771789 | ... W8: =Model!W34 -> 5.8348337
A9: Debt period flag (within tenor) | B9: flag | C9: =IF(AND(C4>=1,C4<=Assumptions!$B$38),1,0) -> 0 | D9: =IF(AND(D4>=1,D4<=Assumptions!$B$38),1,0) -> 1 | E9: =IF(AND(E4>=1,E4<=Assumptions!$B$38),1,0) -> 1 | F9: =IF(AND(F4>=1,F4<=Assumptions!$B$38),1,0) -> 1 | G9: =IF(AND(G4>=1,G4<=Assumptions!$B$38),1,0) -> 1 | H9: =IF(AND(H4>=1,H4<=Assumptions!$B$38),1,0) -> 1 | I9: =IF(AND(I4>=1,I4<=Assumptions!$B$38),1,0) -> 1 | J9: =IF(AND(J4>=1,J4<=Assumptions!$B$38),1,0) -> 1 | ... W9: =IF(AND(W4>=1,W4<=Assumptions!$B$38),1,0) -> 0
A10: Maximum affordable debt service at target DSCR | B10: USD m | C10: =C9*C8/Assumptions!$B$41 -> 0 | D10: =D9*D8/Assumptions!$B$41 -> 3.7607308 | E10: =E9*E8/Assumptions!$B$41 -> 3.7970648 | F10: =F9*F8/Assumptions!$B$41 -> 3.8336531 | G10: =G9*G8/Assumptions!$B$41 -> 3.8704907 | H10: =H9*H8/Assumptions!$B$41 -> 3.9075724 | I10: =I9*I8/Assumptions!$B$41 -> 3.9448926 | J10: =J9*J8/Assumptions!$B$41 -> 3.9824453 | ... W10: =W9*W8/Assumptions!$B$41 -> 0
A11: Discount factor at senior debt interest rate | B11: x | C11: =IF(C9=0,0,1/(1+Assumptions!$B$39)^C4) -> 0 | D11: =IF(D9=0,0,1/(1+Assumptions!$B$39)^D4) -> 0.92592593 | E11: =IF(E9=0,0,1/(1+Assumptions!$B$39)^E4) -> 0.85733882 | F11: =IF(F9=0,0,1/(1+Assumptions!$B$39)^F4) -> 0.79383224 | G11: =IF(G9=0,0,1/(1+Assumptions!$B$39)^G4) -> 0.73502985 | H11: =IF(H9=0,0,1/(1+Assumptions!$B$39)^H4) -> 0.6805832 | I11: =IF(I9=0,0,1/(1+Assumptions!$B$39)^I4) -> 0.63016963 | J11: =IF(J9=0,0,1/(1+Assumptions!$B$39)^J4) -> 0.5834904 | ... W11: =IF(W9=0,0,1/(1+Assumptions!$B$39)^W4) -> 0
A12: PV of maximum affordable debt service | B12: USD m | C12: =C10*C11 -> 0 | D12: =D10*D11 -> 3.4821581 | E12: =E10*E11 -> 3.2553711 | F12: =F10*F11 -> 3.0432774 | G12: =G10*G11 -> 2.8449262 | H12: =H10*H11 -> 2.6594281 | I12: =I10*I11 -> 2.4859515 | J12: =J10*J11 -> 2.3237186 | ... W12: =W10*W11 -> 0
A14: Sizing test results | C14: Value
A15: (a) Maximum debt supported by the 1.30x DSCR covenant | B15: USD m | C15: =SUM(C12:W12) -> 33.973835
A16: (b) Maximum debt supported by the 70% gearing cap | B16: USD m | C16: =Assumptions!$B$45 -> 42
A17: SENIOR DEBT SIZED (lower of a and b) | B17: USD m | C17: =MIN(C15,C16) -> 33.973835
A18: BINDING CONSTRAINT | C18: =IF(C15<C16,"DSCR covenant binds",IF(C15>C16,"70% gearing cap binds","Both bind equally")) -> DSCR covenant binds
A19: Implied gearing (debt / total construction cost) | B19: % | C19: =C17/Assumptions!$B$15 -> 0.56623058
A20: Debt service scaling factor (1.00 if DSCR binds) | B20: x | C20: =C17/C15 -> 1
A21: Resulting DSCR on the sculpted profile | B21: x | C21: =Assumptions!$B$41/C20 -> 1.3
A22: Headroom of sized debt vs gearing cap | B22: USD m | C22: =C16-C17 -> 8.0261652
A24: 2. SOURCES AND USES AT FINANCIAL CLOSE | C24: USD m | D24: % of total
A25: SOURCES
A26: Senior debt — National Infrastructure Fund | C26: =$C$17 -> 33.973835 | D26: =C26/$C$28 -> 0.54902447
A27: Sponsor equity | C27: =C32-C26 -> 27.906531 | D27: =C27/$C$28 -> 0.45097553
A28: Total sources | C28: =SUM(C26:C27) -> 61.880365 | D28: =C28/$C$28 -> 1
A29: USES
A30: Construction capex (EPC, land, grid connection, development) | C30: =Assumptions!$B$15 -> 60 | D30: =C30/$C$32 -> 0.96961289
A31: Debt service reserve account (6 months forward debt service) | C31: =$C$53 -> 1.8803654 | D31: =C31/$C$32 -> 0.030387109
A32: Total uses | C32: =C30+C31 -> 61.880365 | D32: =C32/$C$32 -> 1
A34: Check: total sources = total uses | C34: =IF(ABS(C28-C32)<0.001,"ok","CHECK") -> ok
A35: Debt : equity ratio | C35: =C26/C32 -> 0.54902447 | D35: =C27/C32 -> 0.45097553
A36: Note: the DSRA is funded by sponsor equity at COD and sits outside the 70% gearing base (see Assumptions, note 8).
A38: 3. SENIOR DEBT REPAYMENT SCHEDULE (sculpted to target DSCR, with cash sweep)
A39: Opening balance | B39: USD m | C39: 0 | D39: =C46 -> 33.973835 | E39: =D46 -> 32.366901 | F39: =E46 -> 30.589629 | G39: =F46 -> 28.628098 | H39: =G46 -> 26.467281 | I39: =H46 -> 24.090956 | J39: =I46 -> 21.481606 | K39: =J46 -> 18.620322 | ... W39: =V46 -> 0
A40: Drawdown at financial close | B40: USD m | C40: =IF(C4=0,$C$17,0) -> 33.973835 | D40: =IF(D4=0,$C$17,0) -> 0 | E40: =IF(E4=0,$C$17,0) -> 0 | F40: =IF(F4=0,$C$17,0) -> 0 | G40: =IF(G4=0,$C$17,0) -> 0 | H40: =IF(H4=0,$C$17,0) -> 0 | I40: =IF(I4=0,$C$17,0) -> 0 | J40: =IF(J4=0,$C$17,0) -> 0 | ... W40: =IF(W4=0,$C$17,0) -> 0
A41: Interest accrued at senior debt rate | B41: USD m | C41: =C39*Assumptions!$B$39 -> 0 | D41: =D39*Assumptions!$B$39 -> 2.7179068 | E41: =E39*Assumptions!$B$39 -> 2.5893521 | F41: =F39*Assumptions!$B$39 -> 2.4471703 | G41: =G39*Assumptions!$B$39 -> 2.2902478 | H41: =H39*Assumptions!$B$39 -> 2.1173825 | I41: =I39*Assumptions!$B$39 -> 1.9272765 | J41: =J39*Assumptions!$B$39 -> 1.7185285 | ... W41: =W39*Assumptions!$B$39 -> 0
A42: Scheduled debt service (sculpted) | B42: USD m | C42: =MIN(C10*$C$20,C39+C41) -> 0 | D42: =MIN(D10*$C$20,D39+D41) -> 3.7607308 | E42: =MIN(E10*$C$20,E39+E41) -> 3.7970648 | F42: =MIN(F10*$C$20,F39+F41) -> 3.8336531 | G42: =MIN(G10*$C$20,G39+G41) -> 3.8704907 | H42: =MIN(H10*$C$20,H39+H41) -> 3.9075724 | I42: =MIN(I10*$C$20,I39+I41) -> 3.9448926 | J42: =MIN(J10*$C$20,J39+J41) -> 3.9824453 | ... W42: =MIN(W10*$C$20,W39+W41) -> 0
A43: of which: scheduled principal | B43: USD m | C43: =C42-C41 -> 0 | D43: =D42-D41 -> 1.042824 | E43: =E42-E41 -> 1.2077127 | F43: =F42-F41 -> 1.3864828 | G43: =G42-G41 -> 1.5802429 | H43: =H42-H41 -> 1.7901899 | I43: =I42-I41 -> 2.0176161 | J43: =J42-J41 -> 2.2639169 | ... W43: =W42-W41 -> 0
A44: Cash sweep principal (50% of surplus cash) | B44: USD m | C44: =MIN(Assumptions!$B$44*Assumptions!$B$43*MAX(0,C8-C42),MAX(0,C39+C40-C43)) -> 0 | D44: =MIN(Assumptions!$B$44*Assumptions!$B$43*MAX(0,D8-D42),MAX(0,D39+D40-D43)) -> 0.56410962 | E44: =MIN(Assumptions!$B$44*Assumptions!$B$43*MAX(0,E8-E42),MAX(0,E39+E40-E43)) -> 0.56955972 | F44: =MIN(Assumptions!$B$44*Assumptions!$B$43*MAX(0,F8-F42),MAX(0,F39+F40-F43)) -> 0.57504796 | G44: =MIN(Assumptions!$B$44*Assumptions!$B$43*MAX(0,G8-G42),MAX(0,G39+G40-G43)) -> 0.5805736 | H44: =MIN(Assumptions!$B$44*Assumptions!$B$43*MAX(0,H8-H42),MAX(0,H39+H40-H43)) -> 0.58613586 | I44: =MIN(Assumptions!$B$44*Assumptions!$B$43*MAX(0,I8-I42),MAX(0,I39+I40-I43)) -> 0.59173389 | J44: =MIN(Assumptions!$B$44*Assumptions!$B$43*MAX(0,J8-J42),MAX(0,J39+J40-J43)) -> 0.5973668 | ... W44: =MIN(Assumptions!$B$44*Assumptions!$B$43*MAX(0,W8-W42),MAX(0,W39+W40-W43)) -> 0
A45: Total principal repaid | B45: USD m | C45: =C43+C44 -> 0 | D45: =D43+D44 -> 1.6069336 | E45: =E43+E44 -> 1.7772724 | F45: =F43+F44 -> 1.9615308 | G45: =G43+G44 -> 2.1608165 | H45: =H43+H44 -> 2.3763257 | I45: =I43+I44 -> 2.60935 | J45: =J43+J44 -> 2.8612837 | ... W45: =W43+W44 -> 0
A46: Closing balance | B46: USD m | C46: =C39+C40-C45 -> 33.973835 | D46: =D39+D40-D45 -> 32.366901 | E46: =E39+E40-E45 -> 30.589629 | F46: =F39+F40-F45 -> 28.628098 | G46: =G39+G40-G45 -> 26.467281 | H46: =H39+H40-H45 -> 24.090956 | I46: =I39+I40-I45 -> 21.481606 | J46: =J39+J40-J45 -> 18.620322 | ... W46: =W39+W40-W45 -> 0
...

Sheet Sensitivities
A1: SENSITIVITY ANALYSIS — PROJECT RETURNS
A2: Grids are driven by the live scenario engine lower down this tab — every number traces to a visible formula. Base case sits in the centre cell (highlighted).
A4: Tariff step size | B4: 0.005 | C4: USD / kWh
A5: Capacity factor step size | B5: 0.015 | C5: percentage points
A6: Capex step size | B6: 5 | C6: USD m
A9: GRID 1 — PROJECT (UNLEVERED) IRR: NET CAPACITY FACTOR vs PPA TARIFF | K9: GRID 3 — PROJECT (UNLEVERED) IRR: TOTAL CAPEX vs NET CAPACITY FACTOR
C10: PPA tariff (USD / kWh) → | M10: Total capex (USD m) →
B11: Project IRR | C11: =Assumptions!$B$23-3*$B$4 -> 0.06 | D11: =C11+$B$4 -> 0.065 | E11: =D11+$B$4 -> 0.07 | F11: =E11+$B$4 -> 0.075 | G11: =F11+$B$4 -> 0.08 | H11: =G11+$B$4 -> 0.085 | I11: =H11+$B$4 -> 0.09 | L11: Project IRR | M11: =Assumptions!$B$15-3*$B$6 -> 45 | N11: =M11+$B$6 -> 50 | O11: =N11+$B$6 -> 55 | P11: =O11+$B$6 -> 60 | Q11: =P11+$B$6 -> 65 | R11: =Q11+$B$6 -> 70 | S11: =R11+$B$6 -> 75
A12: Net capacity factor ↓ | B12: =Assumptions!$B$9-3*$B$5 -> 0.165 | C12: {=INDEX($E$41:$E$89,(ROW()-ROW($B$12))*7+(COLUMN()-COLUMN($B$12)))} -> 0.0085171816 | D12: {=INDEX($E$41:$E$89,(ROW()-ROW($B$12))*7+(COLUMN()-COLUMN($B$12)))} -> 0.016893192 | E12: {=INDEX($E$41:$E$89,(ROW()-ROW($B$12))*7+(COLUMN()-COLUMN($B$12)))} -> 0.024845974 | F12: {=INDEX($E$41:$E$89,(ROW()-ROW($B$12))*7+(COLUMN()-COLUMN($B$12)))} -> 0.03243855 | G12: {=INDEX($E$41:$E$89,(ROW()-ROW($B$12))*7+(COLUMN()-COLUMN($B$12)))} -> 0.039721017 | H12: {=INDEX($E$41:$E$89,(ROW()-ROW($B$12))*7+(COLUMN()-COLUMN($B$12)))} -> 0.046733887 | I12: {=INDEX($E$41:$E$89,(ROW()-ROW($B$12))*7+(COLUMN()-COLUMN($B$12)))} -> 0.053510401 | K12: Capacity factor ↓ | L12: =$B12 -> 0.165 | M12: {=INDEX($F$92:$F$140,(ROW()-ROW($L$12))*7+(COLUMN()-COLUMN($L$12)))} -> 0.058445397 | N12: {=INDEX($F$92:$F$140,(ROW()-ROW($L$12))*7+(COLUMN()-COLUMN($L$12)))} -> 0.048419863 | O12: {=INDEX($F$92:$F$140,(ROW()-ROW($L$12))*7+(COLUMN()-COLUMN($L$12)))} -> 0.039859706 | P12: {=INDEX($F$92:$F$140,(ROW()-ROW($L$12))*7+(COLUMN()-COLUMN($L$12)))} -> 0.03243855 | Q12: {=INDEX($F$92:$F$140,(ROW()-ROW($L$12))*7+(COLUMN()-COLUMN($L$12)))} -> 0.025924153 | R12: {=INDEX($F$92:$F$140,(ROW()-ROW($L$12))*7+(COLUMN()-COLUMN($L$12)))} -> 0.020146043 | S12: {=INDEX($F$92:$F$140,(ROW()-ROW($L$12))*7+(COLUMN()-COLUMN($L$12)))} -> 0.014975799
B13: =B12+$B$5 -> 0.18 | C13: {=INDEX($E$41:$E$89,(ROW()-ROW($B$12))*7+(COLUMN()-COLUMN($B$12)))} -> 0.017632604 | D13: {=INDEX($E$41:$E$89,(ROW()-ROW($B$12))*7+(COLUMN()-COLUMN($B$12)))} -> 0.026251618 | E13: {=INDEX($E$41:$E$89,(ROW()-ROW($B$12))*7+(COLUMN()-COLUMN($B$12)))} -> 0.034453576 | F13: {=INDEX($E$41:$E$89,(ROW()-ROW($B$12))*7+(COLUMN()-COLUMN($B$12)))} -> 0.042300459 | G13: {=INDEX($E$41:$E$89,(ROW()-ROW($B$12))*7+(COLUMN()-COLUMN($B$12)))} -> 0.049841645 | H13: {=INDEX($E$41:$E$89,(ROW()-ROW($B$12))*7+(COLUMN()-COLUMN($B$12)))} -> 0.057117133 | I13: {=INDEX($E$41:$E$89,(ROW()-ROW($B$12))*7+(COLUMN()-COLUMN($B$12)))} -> 0.064159798 | L13: =$B13 -> 0.18 | M13: {=INDEX($F$92:$F$140,(ROW()-ROW($L$12))*7+(COLUMN()-COLUMN($L$12)))} -> 0.070042992 | N13: {=INDEX($F$92:$F$140,(ROW()-ROW($L$12))*7+(COLUMN()-COLUMN($L$12)))} -> 0.059338123 | O13: {=INDEX($F$92:$F$140,(ROW()-ROW($L$12))*7+(COLUMN()-COLUMN($L$12)))} -> 0.050208597 | P13: {=INDEX($F$92:$F$140,(ROW()-ROW($L$12))*7+(COLUMN()-COLUMN($L$12)))} -> 0.042300459 | Q13: {=INDEX($F$92:$F$140,(ROW()-ROW($L$12))*7+(COLUMN()-COLUMN($L$12)))} -> 0.03536263 | R13: {=INDEX($F$92:$F$140,(ROW()-ROW($L$12))*7+(COLUMN()-COLUMN($L$12)))} -> 0.029211304 | S13: {=INDEX($F$92:$F$140,(ROW()-ROW($L$12))*7+(COLUMN()-COLUMN($L$12)))} -> 0.023708352
B14: =B13+$B$5 -> 0.195 | C14: {=INDEX($E$41:$E$89,(ROW()-ROW($B$12))*7+(COLUMN()-COLUMN($B$12)))} -> 0.026251618 | D14: {=INDEX($E$41:$E$89,(ROW()-ROW($B$12))*7+(COLUMN()-COLUMN($B$12)))} -> 0.035120291 | E14: {=INDEX($E$41:$E$89,(ROW()-ROW($B$12))*7+(COLUMN()-COLUMN($B$12)))} -> 0.043577371 | F14: {=INDEX($E$41:$E$89,(ROW()-ROW($B$12))*7+(COLUMN()-COLUMN($B$12)))} -> 0.051684035 | G14: {=INDEX($E$41:$E$89,(ROW()-ROW($B$12))*7+(COLUMN()-COLUMN($B$12)))} -> 0.059489106 | H14: {=INDEX($E$41:$E$89,(ROW()-ROW($B$12))*7+(COLUMN()-COLUMN($B$12)))} -> 0.067032192 | I14: {=INDEX($E$41:$E$89,(ROW()-ROW($B$12))*7+(COLUMN()-COLUMN($B$12)))} -> 0.074345885 | L14: =$B14 -> 0.195 | M14: {=INDEX($F$92:$F$140,(ROW()-ROW($L$12))*7+(COLUMN()-COLUMN($L$12)))} -> 0.081117303 | N14: {=INDEX($F$92:$F$140,(ROW()-ROW($L$12))*7+(COLUMN()-COLUMN($L$12)))} -> 0.069747715 | O14: {=INDEX($F$92:$F$140,(ROW()-ROW($L$12))*7+(COLUMN()-COLUMN($L$12)))} -> 0.060063966 | P14: {=INDEX($F$92:$F$140,(ROW()-ROW($L$12))*7+(COLUMN()-COLUMN($L$12)))} -> 0.051684035 | Q14: {=INDEX($F$92:$F$140,(ROW()-ROW($L$12))*7+(COLUMN()-COLUMN($L$12)))} -> 0.04433772 | R14: {=INDEX($F$92:$F$140,(ROW()-ROW($L$12))*7+(COLUMN()-COLUMN($L$12)))} -> 0.037827732 | S14: {=INDEX($F$92:$F$140,(ROW()-ROW($L$12))*7+(COLUMN()-COLUMN($L$12)))} -> 0.032006142
B15: =B14+$B$5 -> 0.21 | C15: {=INDEX($E$41:$E$89,(ROW()-ROW($B$12))*7+(COLUMN()-COLUMN($B$12)))} -> 0.034453576 | D15: {=INDEX($E$41:$E$89,(ROW()-ROW($B$12))*7+(COLUMN()-COLUMN($B$12)))} -> 0.043577371 | E15: {=INDEX($E$41:$E$89,(ROW()-ROW($B$12))*7+(COLUMN()-COLUMN($B$12)))} -> 0.052294578 | F15: {=INDEX($E$41:$E$89,(ROW()-ROW($B$12))*7+(COLUMN()-COLUMN($B$12)))} -> 0.060665745 | G15: {=INDEX($E$41:$E$89,(ROW()-ROW($B$12))*7+(COLUMN()-COLUMN($B$12)))} -> 0.068739261 | H15: {=INDEX($E$41:$E$89,(ROW()-ROW($B$12))*7+(COLUMN()-COLUMN($B$12)))} -> 0.076554428 | I15: {=INDEX($E$41:$E$89,(ROW()-ROW($B$12))*7+(COLUMN()-COLUMN($B$12)))} -> 0.084143615 | L15: =$B15 -> 0.21 | M15: {=INDEX($F$92:$F$140,(ROW()-ROW($L$12))*7+(COLUMN()-COLUMN($L$12)))} -> 0.091758396 | N15: {=INDEX($F$92:$F$140,(ROW()-ROW($L$12))*7+(COLUMN()-COLUMN($L$12)))} -> 0.079733801 | O15: {=INDEX($F$92:$F$140,(ROW()-ROW($L$12))*7+(COLUMN()-COLUMN($L$12)))} -> 0.069506456 | P15: {=INDEX($F$92:$F$140,(ROW()-ROW($L$12))*7+(COLUMN()-COLUMN($L$12)))} -> 0.060665745 | Q15: {=INDEX($F$92:$F$140,(ROW()-ROW($L$12))*7+(COLUMN()-COLUMN($L$12)))} -> 0.052922032 | R15: {=INDEX($F$92:$F$140,(ROW()-ROW($L$12))*7+(COLUMN()-COLUMN($L$12)))} -> 0.046064353 | S15: {=INDEX($F$92:$F$140,(ROW()-ROW($L$12))*7+(COLUMN()-COLUMN($L$12)))} -> 0.039934868
B16: =B15+$B$5 -> 0.225 | C16: {=INDEX($E$41:$E$89,(ROW()-ROW($B$12))*7+(COLUMN()-COLUMN($B$12)))} -> 0.042300459 | D16: {=INDEX($E$41:$E$89,(ROW()-ROW($B$12))*7+(COLUMN()-COLUMN($B$12)))} -> 0.051684035 | E16: {=INDEX($E$41:$E$89,(ROW()-ROW($B$12))*7+(COLUMN()-COLUMN($B$12)))} -> 0.060665745 | F16: {=INDEX($E$41:$E$89,(ROW()-ROW($B$12))*7+(COLUMN()-COLUMN($B$12)))} -> 0.069305636 | G16: {=INDEX($E$41:$E$89,(ROW()-ROW($B$12))*7+(COLUMN()-COLUMN($B$12)))} -> 0.077651751 | H16: {=INDEX($E$41:$E$89,(ROW()-ROW($B$12))*7+(COLUMN()-COLUMN($B$12)))} -> 0.085743147 | I16: {=INDEX($E$41:$E$89,(ROW()-ROW($B$12))*7+(COLUMN()-COLUMN($B$12)))} -> 0.093612013 | L16: =$B16 -> 0.225 | M16: {=INDEX($F$92:$F$140,(ROW()-ROW($L$12))*7+(COLUMN()-COLUMN($L$12)))} -> 0.10203618 | N16: {=INDEX($F$92:$F$140,(ROW()-ROW($L$12))*7+(COLUMN()-COLUMN($L$12)))} -> 0.089362756 | O16: {=INDEX($F$92:$F$140,(ROW()-ROW($L$12))*7+(COLUMN()-COLUMN($L$12)))} -> 0.078599161 | P16: {=INDEX($F$92:$F$140,(ROW()-ROW($L$12))*7+(COLUMN()-COLUMN($L$12)))} -> 0.069305636 | Q16: {=INDEX($F$92:$F$140,(ROW()-ROW($L$12))*7+(COLUMN()-COLUMN($L$12)))} -> 0.061172778 | R16: {=INDEX($F$92:$F$140,(ROW()-ROW($L$12))*7+(COLUMN()-COLUMN($L$12)))} -> 0.05397574 | S16: {=INDEX($F$92:$F$140,(ROW()-ROW($L$12))*7+(COLUMN()-COLUMN($L$12)))} -> 0.047546642
B17: =B16+$B$5 -> 0.24 | C17: {=INDEX($E$41:$E$89,(ROW()-ROW($B$12))*7+(COLUMN()-COLUMN($B$12)))} -> 0.049841645 | D17: {=INDEX($E$41:$E$89,(ROW()-ROW($B$12))*7+(COLUMN()-COLUMN($B$12)))} -> 0.059489106 | E17: {=INDEX($E$41:$E$89,(ROW()-ROW($B$12))*7+(COLUMN()-COLUMN($B$12)))} -> 0.068739261 | F17: {=INDEX($E$41:$E$89,(ROW()-ROW($B$12))*7+(COLUMN()-COLUMN($B$12)))} -> 0.077651751 | G17: {=INDEX($E$41:$E$89,(ROW()-ROW($B$12))*7+(COLUMN()-COLUMN($B$12)))} -> 0.086274338 | H17: {=INDEX($E$41:$E$89,(ROW()-ROW($B$12))*7+(COLUMN()-COLUMN($B$12)))} -> 0.094645877 | I17: {=INDEX($E$41:$E$89,(ROW()-ROW($B$12))*7+(COLUMN()-COLUMN($B$12)))} -> 0.10279841 | L17: =$B17 -> 0.24 | M17: {=INDEX($F$92:$F$140,(ROW()-ROW($L$12))*7+(COLUMN()-COLUMN($L$12)))} -> 0.112006 | N17: {=INDEX($F$92:$F$140,(ROW()-ROW($L$12))*7+(COLUMN()-COLUMN($L$12)))} -> 0.098687336 | O17: {=INDEX($F$92:$F$140,(ROW()-ROW($L$12))*7+(COLUMN()-COLUMN($L$12)))} -> 0.087392401 | P17: {=INDEX($F$92:$F$140,(ROW()-ROW($L$12))*7+(COLUMN()-COLUMN($L$12)))} -> 0.077651751 | Q17: {=INDEX($F$92:$F$140,(ROW()-ROW($L$12))*7+(COLUMN()-COLUMN($L$12)))} -> 0.069135873 | R17: {=INDEX($F$92:$F$140,(ROW()-ROW($L$12))*7+(COLUMN()-COLUMN($L$12)))} -> 0.061605818 | S17: {=INDEX($F$92:$F$140,(ROW()-ROW($L$12))*7+(COLUMN()-COLUMN($L$12)))} -> 0.054883522
B18: =B17+$B$5 -> 0.255 | C18: {=INDEX($E$41:$E$89,(ROW()-ROW($B$12))*7+(COLUMN()-COLUMN($B$12)))} -> 0.057117133 | D18: {=INDEX($E$41:$E$89,(ROW()-ROW($B$12))*7+(COLUMN()-COLUMN($B$12)))} -> 0.067032192 | E18: {=INDEX($E$41:$E$89,(ROW()-ROW($B$12))*7+(COLUMN()-COLUMN($B$12)))} -> 0.076554428 | F18: {=INDEX($E$41:$E$89,(ROW()-ROW($B$12))*7+(COLUMN()-COLUMN($B$12)))} -> 0.085743147 | G18: {=INDEX($E$41:$E$89,(ROW()-ROW($B$12))*7+(COLUMN()-COLUMN($B$12)))} -> 0.094645877 | H18: {=INDEX($E$41:$E$89,(ROW()-ROW($B$12))*7+(COLUMN()-COLUMN($B$12)))} -> 0.1033013 | I18: {=INDEX($E$41:$E$89,(ROW()-ROW($B$12))*7+(COLUMN()-COLUMN($B$12)))} -> 0.11174133 | L18: =$B18 -> 0.255 | M18: {=INDEX($F$92:$F$140,(ROW()-ROW($L$12))*7+(COLUMN()-COLUMN($L$12)))} -> 0.12171244 | N18: {=INDEX($F$92:$F$140,(ROW()-ROW($L$12))*7+(COLUMN()-COLUMN($L$12)))} -> 0.10775017 | O18: {=INDEX($F$92:$F$140,(ROW()-ROW($L$12))*7+(COLUMN()-COLUMN($L$12)))} -> 0.095926966 | P18: {=INDEX($F$92:$F$140,(ROW()-ROW($L$12))*7+(COLUMN()-COLUMN($L$12)))} -> 0.085743147 | Q18: {=INDEX($F$92:$F$140,(ROW()-ROW($L$12))*7+(COLUMN()-COLUMN($L$12)))} -> 0.076848745 | R18: {=INDEX($F$92:$F$140,(ROW()-ROW($L$12))*7+(COLUMN()-COLUMN($L$12)))} -> 0.068990481 | S18: {=INDEX($F$92:$F$140,(ROW()-ROW($L$12))*7+(COLUMN()-COLUMN($L$12)))} -> 0.061979964
A21: GRID 2 — PROJECT NPV AT 10% DISCOUNT RATE (USD m): CAPACITY FACTOR vs PPA TARIFF
C22: PPA tariff (USD / kWh) →
B23: NPV (USD m) | C23: =C$11 -> 0.06 | D23: =D$11 -> 0.065 | E23: =E$11 -> 0.07 | F23: =F$11 -> 0.075 | G23: =G$11 -> 0.08 | H23: =H$11 -> 0.085 | I23: =I$11 -> 0.09
A24: Net capacity factor ↓ | B24: =$B12 -> 0.165 | C24: {=INDEX($F$41:$F$89,(ROW()-ROW($B$24))*7+(COLUMN()-COLUMN($B$24)))} -> -32.555476 | D24: {=INDEX($F$41:$F$89,(ROW()-ROW($B$24))*7+(COLUMN()-COLUMN($B$24)))} -> -30.175417 | E24: {=INDEX($F$41:$F$89,(ROW()-ROW($B$24))*7+(COLUMN()-COLUMN($B$24)))} -> -27.795357 | F24: {=INDEX($F$41:$F$89,(ROW()-ROW($B$24))*7+(COLUMN()-COLUMN($B$24)))} -> -25.415298 | G24: {=INDEX($F$41:$F$89,(ROW()-ROW($B$24))*7+(COLUMN()-COLUMN($B$24)))} -> -23.035238 | H24: {=INDEX($F$41:$F$89,(ROW()-ROW($B$24))*7+(COLUMN()-COLUMN($B$24)))} -> -20.655179 | I24: {=INDEX($F$41:$F$89,(ROW()-ROW($B$24))*7+(COLUMN()-COLUMN($B$24)))} -> -18.275119
B25: =$B13 -> 0.18 | C25: {=INDEX($F$41:$F$89,(ROW()-ROW($B$24))*7+(COLUMN()-COLUMN($B$24)))} -> -29.959048 | D25: {=INDEX($F$41:$F$89,(ROW()-ROW($B$24))*7+(COLUMN()-COLUMN($B$24)))} -> -27.362619 | E25: {=INDEX($F$41:$F$89,(ROW()-ROW($B$24))*7+(COLUMN()-COLUMN($B$24)))} -> -24.766191 | F25: {=INDEX($F$41:$F$89,(ROW()-ROW($B$24))*7+(COLUMN()-COLUMN($B$24)))} -> -22.169762 | G25: {=INDEX($F$41:$F$89,(ROW()-ROW($B$24))*7+(COLUMN()-COLUMN($B$24)))} -> -19.573334 | H25: {=INDEX($F$41:$F$89,(ROW()-ROW($B$24))*7+(COLUMN()-COLUMN($B$24)))} -> -16.976905 | I25: {=INDEX($F$41:$F$89,(ROW()-ROW($B$24))*7+(COLUMN()-COLUMN($B$24)))} -> -14.380477
B26: =$B14 -> 0.195 | C26: {=INDEX($F$41:$F$89,(ROW()-ROW($B$24))*7+(COLUMN()-COLUMN($B$24)))} -> -27.362619 | D26: {=INDEX($F$41:$F$89,(ROW()-ROW($B$24))*7+(COLUMN()-COLUMN($B$24)))} -> -24.549822 | E26: {=INDEX($F$41:$F$89,(ROW()-ROW($B$24))*7+(COLUMN()-COLUMN($B$24)))} -> -21.737024 | F26: {=INDEX($F$41:$F$89,(ROW()-ROW($B$24))*7+(COLUMN()-COLUMN($B$24)))} -> -18.924227 | G26: {=INDEX($F$41:$F$89,(ROW()-ROW($B$24))*7+(COLUMN()-COLUMN($B$24)))} -> -16.111429 | H26: {=INDEX($F$41:$F$89,(ROW()-ROW($B$24))*7+(COLUMN()-COLUMN($B$24)))} -> -13.298632 | I26: {=INDEX($F$41:$F$89,(ROW()-ROW($B$24))*7+(COLUMN()-COLUMN($B$24)))} -> -10.485834
B27: =$B15 -> 0.21 | C27: {=INDEX($F$41:$F$89,(ROW()-ROW($B$24))*7+(COLUMN()-COLUMN($B$24)))} -> -24.766191 | D27: {=INDEX($F$41:$F$89,(ROW()-ROW($B$24))*7+(COLUMN()-COLUMN($B$24)))} -> -21.737024 | E27: {=INDEX($F$41:$F$89,(ROW()-ROW($B$24))*7+(COLUMN()-COLUMN($B$24)))} -> -18.707858 | F27: {=INDEX($F$41:$F$89,(ROW()-ROW($B$24))*7+(COLUMN()-COLUMN($B$24)))} -> -15.678691 | G27: {=INDEX($F$41:$F$89,(ROW()-ROW($B$24))*7+(COLUMN()-COLUMN($B$24)))} -> -12.649524 | H27: {=INDEX($F$41:$F$89,(ROW()-ROW($B$24))*7+(COLUMN()-COLUMN($B$24)))} -> -9.6203578 | I27: {=INDEX($F$41:$F$89,(ROW()-ROW($B$24))*7+(COLUMN()-COLUMN($B$24)))} -> -6.5911912
B28: =$B16 -> 0.225 | C28: {=INDEX($F$41:$F$89,(ROW()-ROW($B$24))*7+(COLUMN()-COLUMN($B$24)))} -> -22.169762 | D28: {=INDEX($F$41:$F$89,(ROW()-ROW($B$24))*7+(COLUMN()-COLUMN($B$24)))} -> -18.924227 | E28: {=INDEX($F$41:$F$89,(ROW()-ROW($B$24))*7+(COLUMN()-COLUMN($B$24)))} -> -15.678691 | F28: {=INDEX($F$41:$F$89,(ROW()-ROW($B$24))*7+(COLUMN()-COLUMN($B$24)))} -> -12.433155 | G28: {=INDEX($F$41:$F$89,(ROW()-ROW($B$24))*7+(COLUMN()-COLUMN($B$24)))} -> -9.1876197 | H28: {=INDEX($F$41:$F$89,(ROW()-ROW($B$24))*7+(COLUMN()-COLUMN($B$24)))} -> -5.9420841 | I28: {=INDEX($F$41:$F$89,(ROW()-ROW($B$24))*7+(COLUMN()-COLUMN($B$24)))} -> -2.6965485
B29: =$B17 -> 0.24 | C29: {=INDEX($F$41:$F$89,(ROW()-ROW($B$24))*7+(COLUMN()-COLUMN($B$24)))} -> -19.573334 | D29: {=INDEX($F$41:$F$89,(ROW()-ROW($B$24))*7+(COLUMN()-COLUMN($B$24)))} -> -16.111429 | E29: {=INDEX($F$41:$F$89,(ROW()-ROW($B$24))*7+(COLUMN()-COLUMN($B$24)))} -> -12.649524 | F29: {=INDEX($F$41:$F$89,(ROW()-ROW($B$24))*7+(COLUMN()-COLUMN($B$24)))} -> -9.1876197 | G29: {=INDEX($F$41:$F$89,(ROW()-ROW($B$24))*7+(COLUMN()-COLUMN($B$24)))} -> -5.7257151 | H29: {=INDEX($F$41:$F$89,(ROW()-ROW($B$24))*7+(COLUMN()-COLUMN($B$24)))} -> -2.2638104 | I29: {=INDEX($F$41:$F$89,(ROW()-ROW($B$24))*7+(COLUMN()-COLUMN($B$24)))} -> 1.1980942
B30: =$B18 -> 0.255 | C30: {=INDEX($F$41:$F$89,(ROW()-ROW($B$24))*7+(COLUMN()-COLUMN($B$24)))} -> -16.976905 | D30: {=INDEX($F$41:$F$89,(ROW()-ROW($B$24))*7+(COLUMN()-COLUMN($B$24)))} -> -13.298632 | E30: {=INDEX($F$41:$F$89,(ROW()-ROW($B$24))*7+(COLUMN()-COLUMN($B$24)))} -> -9.6203578 | F30: {=INDEX($F$41:$F$89,(ROW()-ROW($B$24))*7+(COLUMN()-COLUMN($B$24)))} -> -5.9420841 | G30: {=INDEX($F$41:$F$89,(ROW()-ROW($B$24))*7+(COLUMN()-COLUMN($B$24)))} -> -2.2638104 | H30: {=INDEX($F$41:$F$89,(ROW()-ROW($B$24))*7+(COLUMN()-COLUMN($B$24)))} -> 1.4144633 | I30: {=INDEX($F$41:$F$89,(ROW()-ROW($B$24))*7+(COLUMN()-COLUMN($B$24)))} -> 5.092737
A31: Base case is outlined in red. The scenario engine rows below (grouped — click + to expand) contain the full 21-year cash flow for each of the 98 scenarios; the grids simply INDEX into them, so no static values are used anywhere.
A32: ▼ SCENARIO ENGINE (grouped — expand to audit)
A33: SCENARIO ENGINE — SHARED YEAR-BY-YEAR DRIVERS (identical across all scenarios)
G34: Year → | H34: 0 | I34: =H34+1 -> 1 | J34: =I34+1 -> 2 | K34: =J34+1 -> 3 | L34: =K34+1 -> 4 | M34: =L34+1 -> 5 | N34: =M34+1 -> 6 | O34: =N34+1 -> 7 | P34: =O34+1 -> 8 | ... AB34: =AA34+1 -> 20
G35: Tariff escalation factor | H35: =IF(OR(H34=0,H34>Assumptions!$B$20),0,(1+Assumptions!$B$24)^(H34-1)) -> 0 | I35: =IF(OR(I34=0,I34>Assumptions!$B$20),0,(1+Assumptions!$B$24)^(I34-1)) -> 1 | J35: =IF(OR(J34=0,J34>Assumptions!$B$20),0,(1+Assumptions!$B$24)^(J34-1)) -> 1.015 | K35: =IF(OR(K34=0,K34>Assumptions!$B$20),0,(1+Assumptions!$B$24)^(K34-1)) -> 1.030225 | L35: =IF(OR(L34=0,L34>Assumptions!$B$20),0,(1+Assumptions!$B$24)^(L34-1)) -> 1.0456784 | M35: =IF(OR(M34=0,M34>Assumptions!$B$20),0,(1+Assumptions!$B$24)^(M34-1)) -> 1.0613636 | N35: =IF(OR(N34=0,N34>Assumptions!$B$20),0,(1+Assumptions!$B$24)^(N34-1)) -> 1.077284 | O35: =IF(OR(O34=0,O34>Assumptions!$B$20),0,(1+Assumptions!$B$24)^(O34-1)) -> 1.0934433 | ... AB35: =IF(OR(AB34=0,AB34>Assumptions!$B$20),0,(1+Assumptions!$B$24)^(AB34-1)) -> 1.3269507
G36: Operating cost (USD m) | H36: =IF(OR(H34=0,H34>Assumptions!$B$20),0,Assumptions!$B$26*(1+Assumptions!$B$27)^(H34-1)) -> 0 | I36: =IF(OR(I34=0,I34>Assumptions!$B$20),0,Assumptions!$B$26*(1+Assumptions!$B$27)^(I34-1)) -> 1.2 | J36: =IF(OR(J34=0,J34>Assumptions!$B$20),0,Assumptions!$B$26*(1+Assumptions!$B$27)^(J34-1)) -> 1.236 | K36: =IF(OR(K34=0,K34>Assumptions!$B$20),0,Assumptions!$B$26*(1+Assumptions!$B$27)^(K34-1)) -> 1.27308 | L36: =IF(OR(L34=0,L34>Assumptions!$B$20),0,Assumptions!$B$26*(1+Assumptions!$B$27)^(L34-1)) -> 1.3112724 | M36: =IF(OR(M34=0,M34>Assumptions!$B$20),0,Assumptions!$B$26*(1+Assumptions!$B$27)^(M34-1)) -> 1.3506106 | N36: =IF(OR(N34=0,N34>Assumptions!$B$20),0,Assumptions!$B$26*(1+Assumptions!$B$27)^(N34-1)) -> 1.3911289 | O36: =IF(OR(O34=0,O34>Assumptions!$B$20),0,Assumptions!$B$26*(1+Assumptions!$B$27)^(O34-1)) -> 1.4328628 | ... AB36: =IF(OR(AB34=0,AB34>Assumptions!$B$20),0,Assumptions!$B$26*(1+Assumptions!$B$27)^(AB34-1)) -> 2.1042073
G37: Depreciation (USD m) | H37: =IF(AND(H34>=1,H34<=Assumptions!$B$31),Assumptions!$B$15/Assumptions!$B$31,0) -> 0 | I37: =IF(AND(I34>=1,I34<=Assumptions!$B$31),Assumptions!$B$15/Assumptions!$B$31,0) -> 3 | J37: =IF(AND(J34>=1,J34<=Assumptions!$B$31),Assumptions!$B$15/Assumptions!$B$31,0) -> 3 | K37: =IF(AND(K34>=1,K34<=Assumptions!$B$31),Assumptions!$B$15/Assumptions!$B$31,0) -> 3 | L37: =IF(AND(L34>=1,L34<=Assumptions!$B$31),Assumptions!$B$15/Assumptions!$B$31,0) -> 3 | M37: =IF(AND(M34>=1,M34<=Assumptions!$B$31),Assumptions!$B$15/Assumptions!$B$31,0) -> 3 | N37: =IF(AND(N34>=1,N34<=Assumptions!$B$31),Assumptions!$B$15/Assumptions!$B$31,0) -> 3 | O37: =IF(AND(O34>=1,O34<=Assumptions!$B$31),Assumptions!$B$15/Assumptions!$B$31,0) -> 3 | ... AB37: =IF(AND(AB34>=1,AB34<=Assumptions!$B$31),Assumptions!$B$15/Assumptions!$B$31,0) -> 3
G38: Capex (USD m) | H38: =IF(H34=0,-Assumptions!$B$15,0) -> -60 | I38: =IF(I34=0,-Assumptions!$B$15,0) -> 0 | J38: =IF(J34=0,-Assumptions!$B$15,0) -> 0 | K38: =IF(K34=0,-Assumptions!$B$15,0) -> 0 | L38: =IF(L34=0,-Assumptions!$B$15,0) -> 0 | M38: =IF(M34=0,-Assumptions!$B$15,0) -> 0 | N38: =IF(N34=0,-Assumptions!$B$15,0) -> 0 | O38: =IF(O34=0,-Assumptions!$B$15,0) -> 0 | ... AB38: =IF(AB34=0,-Assumptions!$B$15,0) -> 0
A40: Scenario # | B40: Capacity factor | C40: Net gen (GWh) | D40: Tariff (USD/kWh) | E40: Project IRR | F40: NPV @ WACC | H40: Unlevered free cash flow by year (USD m)
A41: =ROW()-40 -> 1 | B41: {=INDEX($B$12:$B$18,ROUNDUP((ROW()-40)/7,0))} -> 0.165 | C41: =Assumptions!$B$10*$B41 -> 72.27 | D41: {=INDEX($C$11:$I$11,MOD(ROW()-41,7)+1)} -> 0.06 | E41: =IRR(H41:AB41) -> 0.0085171816 | F41: =H41+NPV(Assumptions!$B$34,I41:AB41) -> -32.555476 | H41: =H$38+IF(H$35=0,0,($C41*$D41*H$35)-H$36-MAX(0,($C41*$D41*H$35)-H$36-H$37)*Assumptions!$B$33) -> -60 | I41: =I$38+IF(I$35=0,0,($C41*$D41*I$35)-I$36-MAX(0,($C41*$D41*I$35)-I$36-I$37)*Assumptions!$B$33) -> 3.09534 | J41: =J$38+IF(J$35=0,0,($C41*$D41*J$35)-J$36-MAX(0,($C41*$D41*J$35)-J$36-J$37)*Assumptions!$B$33) -> 3.1156701 | K41: =K$38+IF(K$35=0,0,($C41*$D41*K$35)-K$36-MAX(0,($C41*$D41*K$35)-K$36-K$37)*Assumptions!$B$33) -> 3.1359272 | L41: =L$38+IF(L$35=0,0,($C41*$D41*L$35)-L$36-MAX(0,($C41*$D41*L$35)-L$36-L$37)*Assumptions!$B$33) -> 3.1560987 | M41: =M$38+IF(M$35=0,0,($C41*$D41*M$35)-M$36-MAX(0,($C41*$D41*M$35)-M$36-M$37)*Assumptions!$B$33) -> 3.1761718 | N41: =N$38+IF(N$35=0,0,($C41*$D41*N$35)-N$36-MAX(0,($C41*$D41*N$35)-N$36-N$37)*Assumptions!$B$33) -> 3.196133 | O41: =O$38+IF(O$35=0,0,($C41*$D41*O$35)-O$36-MAX(0,($C41*$D41*O$35)-O$36-O$37)*Assumptions!$B$33) -> 3.2159681 | ... AB41: =AB$38+IF(AB$35=0,0,($C41*$D41*AB$35)-AB$36-MAX(0,($C41*$D41*AB$35)-AB$36-AB$37)*Assumptions!$B$33) -> 3.4548016
A42: =ROW()-40 -> 2 | B42: {=INDEX($B$12:$B$18,ROUNDUP((ROW()-40)/7,0))} -> 0.165 | C42: =Assumptions!$B$10*$B42 -> 72.27 | D42: {=INDEX($C$11:$I$11,MOD(ROW()-41,7)+1)} -> 0.065 | E42: =IRR(H42:AB42) -> 0.016893192 | F42: =H42+NPV(Assumptions!$B$34,I42:AB42) -> -30.175417 | H42: =H$38+IF(H$35=0,0,($C42*$D42*H$35)-H$36-MAX(0,($C42*$D42*H$35)-H$36-H$37)*Assumptions!$B$33) -> -60 | I42: =I$38+IF(I$35=0,0,($C42*$D42*I$35)-I$36-MAX(0,($C42*$D42*I$35)-I$36-I$37)*Assumptions!$B$33) -> 3.348285 | J42: =J$38+IF(J$35=0,0,($C42*$D42*J$35)-J$36-MAX(0,($C42*$D42*J$35)-J$36-J$37)*Assumptions!$B$33) -> 3.3724093 | K42: =K$38+IF(K$35=0,0,($C42*$D42*K$35)-K$36-MAX(0,($C42*$D42*K$35)-K$36-K$37)*Assumptions!$B$33) -> 3.3965174 | L42: =L$38+IF(L$35=0,0,($C42*$D42*L$35)-L$36-MAX(0,($C42*$D42*L$35)-L$36-L$37)*Assumptions!$B$33) -> 3.4205978 | M42: =M$38+IF(M$35=0,0,($C42*$D42*M$35)-M$36-MAX(0,($C42*$D42*M$35)-M$36-M$37)*Assumptions!$B$33) -> 3.4446384 | N42: =N$38+IF(N$35=0,0,($C42*$D42*N$35)-N$36-MAX(0,($C42*$D42*N$35)-N$36-N$37)*Assumptions!$B$33) -> 3.4686266 | O42: =O$38+IF(O$35=0,0,($C42*$D42*O$35)-O$36-MAX(0,($C42*$D42*O$35)-O$36-O$37)*Assumptions!$B$33) -> 3.4925492 | ... AB42: =AB$38+IF(AB$35=0,0,($C42*$D42*AB$35)-AB$36-MAX(0,($C42*$D42*AB$35)-AB$36-AB$37)*Assumptions!$B$33) -> 3.7904471
A43: =ROW()-40 -> 3 | B43: {=INDEX($B$12:$B$18,ROUNDUP((ROW()-40)/7,0))} -> 0.165 | C43: =Assumptions!$B$10*$B43 -> 72.27 | D43: {=INDEX($C$11:$I$11,MOD(ROW()-41,7)+1)} -> 0.07 | E43: =IRR(H43:AB43) -> 0.024845974 | F43: =H43+NPV(Assumptions!$B$34,I43:AB43) -> -27.795357 | H43: =H$38+IF(H$35=0,0,($C43*$D43*H$35)-H$36-MAX(0,($C43*$D43*H$35)-H$36-H$37)*Assumptions!$B$33) -> -60 | I43: =I$38+IF(I$35=0,0,($C43*$D43*I$35)-I$36-MAX(0,($C43*$D43*I$35)-I$36-I$37)*Assumptions!$B$33) -> 3.60123 | J43: =J$38+IF(J$35=0,0,($C43*$D43*J$35)-J$36-MAX(0,($C43*$D43*J$35)-J$36-J$37)*Assumptions!$B$33) -> 3.6291485 | K43: =K$38+IF(K$35=0,0,($C43*$D43*K$35)-K$36-MAX(0,($C43*$D43*K$35)-K$36-K$37)*Assumptions!$B$33) -> 3.6571077 | L43: =L$38+IF(L$35=0,0,($C43*$D43*L$35)-L$36-MAX(0,($C43*$D43*L$35)-L$36-L$37)*Assumptions!$B$33) -> 3.685097 | M43: =M$38+IF(M$35=0,0,($C43*$D43*M$35)-M$36-MAX(0,($C43*$D43*M$35)-M$36-M$37)*Assumptions!$B$33) -> 3.713105 | N43: =N$38+IF(N$35=0,0,($C43*$D43*N$35)-N$36-MAX(0,($C43*$D43*N$35)-N$36-N$37)*Assumptions!$B$33) -> 3.7411202 | O43: =O$38+IF(O$35=0,0,($C43*$D43*O$35)-O$36-MAX(0,($C43*$D43*O$35)-O$36-O$37)*Assumptions!$B$33) -> 3.7691302 | ... AB43: =AB$38+IF(AB$35=0,0,($C43*$D43*AB$35)-AB$36-MAX(0,($C43*$D43*AB$35)-AB$36-AB$37)*Assumptions!$B$33) -> 4.1260927
A44: =ROW()-40 -> 4 | B44: {=INDEX($B$12:$B$18,ROUNDUP((ROW()-40)/7,0))} -> 0.165 | C44: =Assumptions!$B$10*$B44 -> 72.27 | D44: {=INDEX($C$11:$I$11,MOD(ROW()-41,7)+1)} -> 0.075 | E44: =IRR(H44:AB44) -> 0.03243855 | F44: =H44+NPV(Assumptions!$B$34,I44:AB44) -> -25.415298 | H44: =H$38+IF(H$35=0,0,($C44*$D44*H$35)-H$36-MAX(0,($C44*$D44*H$35)-H$36-H$37)*Assumptions!$B$33) -> -60 | I44: =I$38+IF(I$35=0,0,($C44*$D44*I$35)-I$36-MAX(0,($C44*$D44*I$35)-I$36-I$37)*Assumptions!$B$33) -> 3.854175 | J44: =J$38+IF(J$35=0,0,($C44*$D44*J$35)-J$36-MAX(0,($C44*$D44*J$35)-J$36-J$37)*Assumptions!$B$33) -> 3.8858876 | K44: =K$38+IF(K$35=0,0,($C44*$D44*K$35)-K$36-MAX(0,($C44*$D44*K$35)-K$36-K$37)*Assumptions!$B$33) -> 3.9176979 | L44: =L$38+IF(L$35=0,0,($C44*$D44*L$35)-L$36-MAX(0,($C44*$D44*L$35)-L$36-L$37)*Assumptions!$B$33) -> 3.9495961 | M44: =M$38+IF(M$35=0,0,($C44*$D44*M$35)-M$36-MAX(0,($C44*$D44*M$35)-M$36-M$37)*Assumptions!$B$33) -> 3.9815716 | N44: =N$38+IF(N$35=0,0,($C44*$D44*N$35)-N$36-MAX(0,($C44*$D44*N$35)-N$36-N$37)*Assumptions!$B$33) -> 4.0136138 | O44: =O$38+IF(O$35=0,0,($C44*$D44*O$35)-O$36-MAX(0,($C44*$D44*O$35)-O$36-O$37)*Assumptions!$B$33) -> 4.0457112 | ... AB44: =AB$38+IF(AB$35=0,0,($C44*$D44*AB$35)-AB$36-MAX(0,($C44*$D44*AB$35)-AB$36-AB$37)*Assumptions!$B$33) -> 4.4617383
A45: =ROW()-40 -> 5 | B45: {=INDEX($B$12:$B$18,ROUNDUP((ROW()-40)/7,0))} -> 0.165 | C45: =Assumptions!$B$10*$B45 -> 72.27 | D45: {=INDEX($C$11:$I$11,MOD(ROW()-41,7)+1)} -> 0.08 | E45: =IRR(H45:AB45) -> 0.039721017 | F45: =H45+NPV(Assumptions!$B$34,I45:AB45) -> -23.035238 | H45: =H$38+IF(H$35=0,0,($C45*$D45*H$35)-H$36-MAX(0,($C45*$D45*H$35)-H$36-H$37)*Assumptions!$B$33) -> -60 | I45: =I$38+IF(I$35=0,0,($C45*$D45*I$35)-I$36-MAX(0,($C45*$D45*I$35)-I$36-I$37)*Assumptions!$B$33) -> 4.10712 | J45: =J$38+IF(J$35=0,0,($C45*$D45*J$35)-J$36-MAX(0,($C45*$D45*J$35)-J$36-J$37)*Assumptions!$B$33) -> 4.1426268 | K45: =K$38+IF(K$35=0,0,($C45*$D45*K$35)-K$36-MAX(0,($C45*$D45*K$35)-K$36-K$37)*Assumptions!$B$33) -> 4.1782882 | L45: =L$38+IF(L$35=0,0,($C45*$D45*L$35)-L$36-MAX(0,($C45*$D45*L$35)-L$36-L$37)*Assumptions!$B$33) -> 4.2140952 | M45: =M$38+IF(M$35=0,0,($C45*$D45*M$35)-M$36-MAX(0,($C45*$D45*M$35)-M$36-M$37)*Assumptions!$B$33) -> 4.2500383 | N45: =N$38+IF(N$35=0,0,($C45*$D45*N$35)-N$36-MAX(0,($C45*$D45*N$35)-N$36-N$37)*Assumptions!$B$33) -> 4.2861074 | O45: =O$38+IF(O$35=0,0,($C45*$D45*O$35)-O$36-MAX(0,($C45*$D45*O$35)-O$36-O$37)*Assumptions!$B$33) -> 4.3222922 | ... AB45: =AB$38+IF(AB$35=0,0,($C45*$D45*AB$35)-AB$36-MAX(0,($C45*$D45*AB$35)-AB$36-AB$37)*Assumptions!$B$33) -> 4.7973838
A46: =ROW()-40 -> 6 | B46: {=INDEX($B$12:$B$18,ROUNDUP((ROW()-40)/7,0))} -> 0.165 | C46: =Assumptions!$B$10*$B46 -> 72.27 | D46: {=INDEX($C$11:$I$11,MOD(ROW()-41,7)+1)} -> 0.085 | E46: =IRR(H46:AB46) -> 0.046733887 | F46: =H46+NPV(Assumptions!$B$34,I46:AB46) -> -20.655179 | H46: =H$38+IF(H$35=0,0,($C46*$D46*H$35)-H$36-MAX(0,($C46*$D46*H$35)-H$36-H$37)*Assumptions!$B$33) -> -60 | I46: =I$38+IF(I$35=0,0,($C46*$D46*I$35)-I$36-MAX(0,($C46*$D46*I$35)-I$36-I$37)*Assumptions!$B$33) -> 4.360065 | J46: =J$38+IF(J$35=0,0,($C46*$D46*J$35)-J$36-MAX(0,($C46*$D46*J$35)-J$36-J$37)*Assumptions!$B$33) -> 4.399366 | K46: =K$38+IF(K$35=0,0,($C46*$D46*K$35)-K$36-MAX(0,($C46*$D46*K$35)-K$36-K$37)*Assumptions!$B$33) -> 4.4388785 | L46: =L$38+IF(L$35=0,0,($C46*$D46*L$35)-L$36-MAX(0,($C46*$D46*L$35)-L$36-L$37)*Assumptions!$B$33) -> 4.4785943 | M46: =M$38+IF(M$35=0,0,($C46*$D46*M$35)-M$36-MAX(0,($C46*$D46*M$35)-M$36-M$37)*Assumptions!$B$33) -> 4.5185049 | N46: =N$38+IF(N$35=0,0,($C46*$D46*N$35)-N$36-MAX(0,($C46*$D46*N$35)-N$36-N$37)*Assumptions!$B$33) -> 4.558601 | O46: =O$38+IF(O$35=0,0,($C46*$D46*O$35)-O$36-MAX(0,($C46*$D46*O$35)-O$36-O$37)*Assumptions!$B$33) -> 4.5988732 | ... AB46: =AB$38+IF(AB$35=0,0,($C46*$D46*AB$35)-AB$36-MAX(0,($C46*$D46*AB$35)-AB$36-AB$37)*Assumptions!$B$33) -> 5.1330294
...

Sheet Outputs
A1: Meridian Solar IPP — SUMMARY OF FINDINGS
A2: Every figure below is a live link to the Model, Debt or Assumptions tab. Change any input and this page updates.
A4: PROJECT ECONOMICS | B4: Unit | C4: Value
A5: Installed capacity | B5: MW | C5: =Assumptions!$B$7 -> 50
A6: Net annual generation | B6: GWh | C6: =Assumptions!$B$11 -> 91.98
A7: Total construction cost | B7: USD m | C7: =Assumptions!$B$15 -> 60
A8: Year 1 revenue | B8: USD m | C8: =Model!$D$12 -> 6.8985
A9: Year 1 EBITDA | B9: USD m | C9: =Model!$D$17 -> 5.6985
A10: Year 1 CFADS | B10: USD m | C10: =Model!$D$34 -> 4.88895
A11: Average annual CFADS (Years 1-20) | B11: USD m | C11: =AVERAGE(Model!$D$34:$W$34) -> 5.3545959
A12: Total lifetime generation | B12: GWh | C12: =Model!$C$49 -> 1839.6
A13: PROJECT IRR (unlevered) | B13: % | C13: =Model!$C$43 -> 0.060665745
A14: PROJECT NPV at 10% discount rate | B14: USD m | C14: =Model!$C$44 -> -15.678691
A15: Simple payback from COD | B15: years | C15: =Model!$C$47 -> 12
A17: FUNDING STRUCTURE — DIF SENIOR DEBT PACKAGE | B17: Unit | C17: Value
A18: Maximum debt under the 70% gearing cap | B18: USD m | C18: =Debt!$C$16 -> 42
A19: Maximum debt under the 1.30x DSCR covenant | B19: USD m | C19: =Debt!$C$15 -> 33.973835
A20: BINDING CONSTRAINT | C20: =Debt!$C$18 -> DSCR covenant binds
A21: Senior debt sized — National Infrastructure Fund | B21: USD m | C21: =Debt!$C$26 -> 33.973835
A22: Sponsor equity (incl. DSRA funding) | B22: USD m | C22: =Debt!$C$27 -> 27.906531
A23: of which: debt service reserve account | B23: USD m | C23: =Debt!$C$31 -> 1.8803654
A24: Total sources = total uses | B24: USD m | C24: =Debt!$C$28 -> 61.880365
A25: Gearing achieved (debt / construction cost) | B25: % | C25: =Debt!$C$19 -> 0.56623058
A26: Unused capacity under the gearing cap | B26: USD m | C26: =Debt!$C$22 -> 8.0261652
A28: RETURNS & COVENANT PERFORMANCE | B28: Unit | C28: Value
A29: EQUITY IRR (post-tax) | B29: % | C29: =Debt!$C$67 -> 0.060358843
A30: Project IRR (unlevered), for comparison | B30: % | C30: =Model!$C$43 -> 0.060665745
A31: Net effect of leverage on equity IRR (after tax shield) | B31: pp | C31: =(C29-C30)*100 -> -0.030690223
A32: Equity cash-on-cash multiple | B32: x | C32: =Debt!$C$74 -> 2.1729642
A33: MINIMUM DSCR across the tenor | B33: x | C33: =Debt!$C$69 -> #NAME?
A34: AVERAGE DSCR across the tenor | B34: x | C34: =Debt!$C$70 -> 1.3
A35: DSCR covenant required by the DIF | B35: x | C35: =Assumptions!$B$40 -> 1.3
A36: Headroom to covenant at the minimum | B36: x | C36: =C33-C35 -> #NAME?
A37: Debt fully repaid in operating year | B37: year | C37: =Debt!$C$72 -> 12
A38: Years repaid ahead of the 15-year tenor | B38: years | C38: =Debt!$C$73 -> 3
A39: Model integrity check (all checks pass) | B39: flag | C39: =IF(AND(Model!$C$46="ok",Debt!$C$34="ok",Debt!$C$76="ok",Debt!$C$77="ok"),"ALL CHECKS PASS","REVIEW REQUIRED") -> ALL CHECKS PASS
A41: CHART SOURCE DATA (live links — do not overwrite)
A42: Operating year | B42: CFADS | C42: Total debt service | E42: Operating year | F42: DSCR (scheduled) | G42: Covenant floor | H42: DSCR incl. cash sweep | I42: Operating year | J42: Senior debt outstanding | K42: Equity cash flow
A43: 1 | B43: {=INDEX(Model!$D$34:$W$34,$A43)} -> 4.88895 | C43: {=INDEX(Debt!$D$47:$W$47,$A43)} -> 4.3248404 | E43: =$A43 -> 1 | F43: {=IF(INDEX(Debt!$D$48:$W$48,$A43)=0,NA(),INDEX(Debt!$D$48:$W$48,$A43))} -> 1.3 | G43: =IF(ISNA(F43),NA(),Assumptions!$B$40) -> 1.3 | H43: {=IF(INDEX(Debt!$D$49:$W$49,$A43)=0,NA(),INDEX(Debt!$D$49:$W$49,$A43))} -> 1.1304348 | I43: =$A43 -> 1 | J43: {=INDEX(Debt!$D$46:$W$46,$A43)} -> 32.366901 | K43: {=INDEX(Debt!$D$63:$W$63,$A43)} -> 1.3554926
A44: =A43+1 -> 2 | B44: {=INDEX(Model!$D$34:$W$34,$A44)} -> 4.9361842 | C44: {=INDEX(Debt!$D$47:$W$47,$A44)} -> 4.3666245 | E44: =$A44 -> 2 | F44: {=IF(INDEX(Debt!$D$48:$W$48,$A44)=0,NA(),INDEX(Debt!$D$48:$W$48,$A44))} -> 1.3 | G44: =IF(ISNA(F44),NA(),Assumptions!$B$40) -> 1.3 | H44: {=IF(INDEX(Debt!$D$49:$W$49,$A44)=0,NA(),INDEX(Debt!$D$49:$W$49,$A44))} -> 1.1304348 | I44: =$A44 -> 2 | J44: {=INDEX(Debt!$D$46:$W$46,$A44)} -> 30.589629 | K44: {=INDEX(Debt!$D$63:$W$63,$A44)} -> 1.3280712
...
